INFO:human_api:--getting single person
ERROR:human_api:64 | 'id'
WARNING:django.request:Method Not Allowed: /people/update-one/
WARNING:django.request:Method Not Allowed: /people/update-one/
WARNING:django.request:Method Not Allowed: /people/update-one/
WARNING:django.request:Method Not Allowed: /people/update-one/
WARNING:django.request:Method Not Allowed: /people/update-one/
WARNING:django.request:Method Not Allowed: /people/update-one/
WARNING:django.request:Method Not Allowed: /people/update-one/
WARNING:django.request:Method Not Allowed: /people/delete-one/
WARNING:django.request:Method Not Allowed: /people/delete-one/
ERROR:human_api:113 | 'id'
WARNING:django.request:Method Not Allowed: /people/delete-one/
WARNING:django.request:Method Not Allowed: /people/delete-one/
WARNING:django.request:Method Not Allowed: /people/delete-one/
WARNING:django.request:Method Not Allowed: /people/delete-one/
WARNING:django.request:Method Not Allowed: /people/delete-one/
ERROR:django.request:Internal Server Error: /people/avg-age-industry/
Traceback (most recent call last):
  File "C:\Users\kunas\Documents\work_in_progress\local\colibri\colibri\lib\site-packages\django\core\handlers\exception.py", line 47, in inner
    response = get_response(request)
  File "C:\Users\kunas\Documents\work_in_progress\local\colibri\colibri\lib\site-packages\django\core\handlers\base.py", line 181, in _get_response
    response = wrapped_callback(request, *callback_args, **callback_kwargs)
  File "C:\Users\kunas\Documents\work_in_progress\local\colibri\colibri\lib\site-packages\django\views\decorators\csrf.py", line 54, in wrapped_view
    return view_func(*args, **kwargs)
  File "C:\Users\kunas\Documents\work_in_progress\local\colibri\colibri\lib\site-packages\rest_framework\viewsets.py", line 125, in view
    return self.dispatch(request, *args, **kwargs)
  File "C:\Users\kunas\Documents\work_in_progress\local\colibri\colibri\lib\site-packages\rest_framework\views.py", line 509, in dispatch
    response = self.handle_exception(exc)
  File "C:\Users\kunas\Documents\work_in_progress\local\colibri\colibri\lib\site-packages\rest_framework\views.py", line 469, in handle_exception
    self.raise_uncaught_exception(exc)
  File "C:\Users\kunas\Documents\work_in_progress\local\colibri\colibri\lib\site-packages\rest_framework\views.py", line 480, in raise_uncaught_exception
    raise exc
  File "C:\Users\kunas\Documents\work_in_progress\local\colibri\colibri\lib\site-packages\rest_framework\views.py", line 506, in dispatch
    response = handler(request, *args, **kwargs)
TypeError: avg_age_industry() takes 0 positional arguments but 2 were given
ERROR:django.request:Internal Server Error: /people/avg-age-industry/
Traceback (most recent call last):
  File "C:\Users\kunas\Documents\work_in_progress\local\colibri\colibri\lib\site-packages\django\core\handlers\exception.py", line 47, in inner
    response = get_response(request)
  File "C:\Users\kunas\Documents\work_in_progress\local\colibri\colibri\lib\site-packages\django\core\handlers\base.py", line 181, in _get_response
    response = wrapped_callback(request, *callback_args, **callback_kwargs)
  File "C:\Users\kunas\Documents\work_in_progress\local\colibri\colibri\lib\site-packages\django\views\decorators\csrf.py", line 54, in wrapped_view
    return view_func(*args, **kwargs)
  File "C:\Users\kunas\Documents\work_in_progress\local\colibri\colibri\lib\site-packages\rest_framework\viewsets.py", line 125, in view
    return self.dispatch(request, *args, **kwargs)
  File "C:\Users\kunas\Documents\work_in_progress\local\colibri\colibri\lib\site-packages\rest_framework\views.py", line 509, in dispatch
    response = self.handle_exception(exc)
  File "C:\Users\kunas\Documents\work_in_progress\local\colibri\colibri\lib\site-packages\rest_framework\views.py", line 469, in handle_exception
    self.raise_uncaught_exception(exc)
  File "C:\Users\kunas\Documents\work_in_progress\local\colibri\colibri\lib\site-packages\rest_framework\views.py", line 480, in raise_uncaught_exception
    raise exc
  File "C:\Users\kunas\Documents\work_in_progress\local\colibri\colibri\lib\site-packages\rest_framework\views.py", line 506, in dispatch
    response = handler(request, *args, **kwargs)
  File "C:\Users\kunas\Documents\work_in_progress\local\colibri\hr\people\views.py", line 159, in avg_age_industry
    df["age"] = df.date_of_birth.apply(lambda x:  self.age(x))
  File "C:\Users\kunas\Documents\work_in_progress\local\colibri\colibri\lib\site-packages\pandas\core\series.py", line 4356, in apply
    return SeriesApply(self, func, convert_dtype, args, kwargs).apply()
  File "C:\Users\kunas\Documents\work_in_progress\local\colibri\colibri\lib\site-packages\pandas\core\apply.py", line 1036, in apply
    return self.apply_standard()
  File "C:\Users\kunas\Documents\work_in_progress\local\colibri\colibri\lib\site-packages\pandas\core\apply.py", line 1095, in apply_standard
    convert=self.convert_dtype,
  File "pandas\_libs\lib.pyx", line 2859, in pandas._libs.lib.map_infer
  File "C:\Users\kunas\Documents\work_in_progress\local\colibri\hr\people\views.py", line 159, in <lambda>
    df["age"] = df.date_of_birth.apply(lambda x:  self.age(x))
TypeError: age() takes 1 positional argument but 2 were given
ERROR:django.request:Internal Server Error: /people/avg-age-industry/
Traceback (most recent call last):
  File "C:\Users\kunas\Documents\work_in_progress\local\colibri\colibri\lib\site-packages\django\core\handlers\exception.py", line 47, in inner
    response = get_response(request)
  File "C:\Users\kunas\Documents\work_in_progress\local\colibri\colibri\lib\site-packages\django\core\handlers\base.py", line 181, in _get_response
    response = wrapped_callback(request, *callback_args, **callback_kwargs)
  File "C:\Users\kunas\Documents\work_in_progress\local\colibri\colibri\lib\site-packages\django\views\decorators\csrf.py", line 54, in wrapped_view
    return view_func(*args, **kwargs)
  File "C:\Users\kunas\Documents\work_in_progress\local\colibri\colibri\lib\site-packages\rest_framework\viewsets.py", line 125, in view
    return self.dispatch(request, *args, **kwargs)
  File "C:\Users\kunas\Documents\work_in_progress\local\colibri\colibri\lib\site-packages\rest_framework\views.py", line 509, in dispatch
    response = self.handle_exception(exc)
  File "C:\Users\kunas\Documents\work_in_progress\local\colibri\colibri\lib\site-packages\rest_framework\views.py", line 469, in handle_exception
    self.raise_uncaught_exception(exc)
  File "C:\Users\kunas\Documents\work_in_progress\local\colibri\colibri\lib\site-packages\rest_framework\views.py", line 480, in raise_uncaught_exception
    raise exc
  File "C:\Users\kunas\Documents\work_in_progress\local\colibri\colibri\lib\site-packages\rest_framework\views.py", line 506, in dispatch
    response = handler(request, *args, **kwargs)
  File "C:\Users\kunas\Documents\work_in_progress\local\colibri\hr\people\views.py", line 161, in avg_age_industry
    df["age"] = df.date_of_birth.apply(lambda x:  self.age(self,x))
  File "C:\Users\kunas\Documents\work_in_progress\local\colibri\colibri\lib\site-packages\pandas\core\series.py", line 4356, in apply
    return SeriesApply(self, func, convert_dtype, args, kwargs).apply()
  File "C:\Users\kunas\Documents\work_in_progress\local\colibri\colibri\lib\site-packages\pandas\core\apply.py", line 1036, in apply
    return self.apply_standard()
  File "C:\Users\kunas\Documents\work_in_progress\local\colibri\colibri\lib\site-packages\pandas\core\apply.py", line 1095, in apply_standard
    convert=self.convert_dtype,
  File "pandas\_libs\lib.pyx", line 2859, in pandas._libs.lib.map_infer
  File "C:\Users\kunas\Documents\work_in_progress\local\colibri\hr\people\views.py", line 161, in <lambda>
    df["age"] = df.date_of_birth.apply(lambda x:  self.age(self,x))
TypeError: age() takes 2 positional arguments but 3 were given
ERROR:django.request:Internal Server Error: /stats/avg-age-industry/
Traceback (most recent call last):
  File "C:\Users\kunas\Documents\work_in_progress\local\colibri\colibri\lib\site-packages\django\core\handlers\exception.py", line 47, in inner
    response = get_response(request)
  File "C:\Users\kunas\Documents\work_in_progress\local\colibri\colibri\lib\site-packages\django\core\handlers\base.py", line 181, in _get_response
    response = wrapped_callback(request, *callback_args, **callback_kwargs)
  File "C:\Users\kunas\Documents\work_in_progress\local\colibri\colibri\lib\site-packages\django\views\decorators\csrf.py", line 54, in wrapped_view
    return view_func(*args, **kwargs)
  File "C:\Users\kunas\Documents\work_in_progress\local\colibri\colibri\lib\site-packages\rest_framework\viewsets.py", line 104, in view
    self = cls(**initkwargs)
TypeError: __init__() got an unexpected keyword argument 'suffix'
ERROR:django.request:Internal Server Error: /stats/avg-age-industry/
Traceback (most recent call last):
  File "C:\Users\kunas\Documents\work_in_progress\local\colibri\colibri\lib\site-packages\django\core\handlers\exception.py", line 47, in inner
    response = get_response(request)
  File "C:\Users\kunas\Documents\work_in_progress\local\colibri\colibri\lib\site-packages\django\core\handlers\base.py", line 181, in _get_response
    response = wrapped_callback(request, *callback_args, **callback_kwargs)
  File "C:\Users\kunas\Documents\work_in_progress\local\colibri\colibri\lib\site-packages\django\views\decorators\csrf.py", line 54, in wrapped_view
    return view_func(*args, **kwargs)
  File "C:\Users\kunas\Documents\work_in_progress\local\colibri\colibri\lib\site-packages\rest_framework\viewsets.py", line 104, in view
    self = cls(**initkwargs)
TypeError: __init__() got an unexpected keyword argument 'suffix'
ERROR:django.request:Internal Server Error: /stats/avg-age-industry/
Traceback (most recent call last):
  File "C:\Users\kunas\Documents\work_in_progress\local\colibri\colibri\lib\site-packages\django\core\handlers\exception.py", line 47, in inner
    response = get_response(request)
  File "C:\Users\kunas\Documents\work_in_progress\local\colibri\colibri\lib\site-packages\django\core\handlers\base.py", line 181, in _get_response
    response = wrapped_callback(request, *callback_args, **callback_kwargs)
  File "C:\Users\kunas\Documents\work_in_progress\local\colibri\colibri\lib\site-packages\django\views\decorators\csrf.py", line 54, in wrapped_view
    return view_func(*args, **kwargs)
  File "C:\Users\kunas\Documents\work_in_progress\local\colibri\colibri\lib\site-packages\rest_framework\viewsets.py", line 104, in view
    self = cls(**initkwargs)
TypeError: __init__() got an unexpected keyword argument 'suffix'
WARNING:django.request:Not Found: /stats/avg-age-industry/
WARNING:django.request:Not Found: /stats/avg-age-industry/
WARNING:django.request:Not Found: /stats/avg-age-industry/
WARNING:django.request:Not Found: /stats/avg-age-industry/
WARNING:django.request:Not Found: /stats/avg-age-industry/
WARNING:django.request:Not Found: /stats/avg-age-industry/
WARNING:django.request:Not Found: /favicon.ico
WARNING:django.request:Not Found: /stats/avg-age-industry/
WARNING:django.request:Not Found: /people/avg-age-industry/
ERROR:django.request:Internal Server Error: /stats/avg-age-by-industry/
Traceback (most recent call last):
  File "C:\Users\kunas\Documents\work_in_progress\local\colibri\colibri\lib\site-packages\django\core\handlers\exception.py", line 47, in inner
    response = get_response(request)
  File "C:\Users\kunas\Documents\work_in_progress\local\colibri\colibri\lib\site-packages\django\core\handlers\base.py", line 181, in _get_response
    response = wrapped_callback(request, *callback_args, **callback_kwargs)
  File "C:\Users\kunas\Documents\work_in_progress\local\colibri\colibri\lib\site-packages\django\views\decorators\csrf.py", line 54, in wrapped_view
    return view_func(*args, **kwargs)
  File "C:\Users\kunas\Documents\work_in_progress\local\colibri\colibri\lib\site-packages\rest_framework\viewsets.py", line 125, in view
    return self.dispatch(request, *args, **kwargs)
  File "C:\Users\kunas\Documents\work_in_progress\local\colibri\colibri\lib\site-packages\rest_framework\views.py", line 509, in dispatch
    response = self.handle_exception(exc)
  File "C:\Users\kunas\Documents\work_in_progress\local\colibri\colibri\lib\site-packages\rest_framework\views.py", line 469, in handle_exception
    self.raise_uncaught_exception(exc)
  File "C:\Users\kunas\Documents\work_in_progress\local\colibri\colibri\lib\site-packages\rest_framework\views.py", line 480, in raise_uncaught_exception
    raise exc
  File "C:\Users\kunas\Documents\work_in_progress\local\colibri\colibri\lib\site-packages\rest_framework\views.py", line 506, in dispatch
    response = handler(request, *args, **kwargs)
  File "C:\Users\kunas\Documents\work_in_progress\local\colibri\hr\people\views.py", line 51, in avg_age_industry
    self.logger.info("{0}".format(json.dumps(request)))
  File "C:\Users\kunas\AppData\Local\Programs\Python\Python37\lib\json\__init__.py", line 231, in dumps
    return _default_encoder.encode(obj)
  File "C:\Users\kunas\AppData\Local\Programs\Python\Python37\lib\json\encoder.py", line 199, in encode
    chunks = self.iterencode(o, _one_shot=True)
  File "C:\Users\kunas\AppData\Local\Programs\Python\Python37\lib\json\encoder.py", line 257, in iterencode
    return _iterencode(o, 0)
  File "C:\Users\kunas\AppData\Local\Programs\Python\Python37\lib\json\encoder.py", line 179, in default
    raise TypeError(f'Object of type {o.__class__.__name__} '
TypeError: Object of type Request is not JSON serializable
WARNING:django.request:Not Found: /stats/avg-age-industry/
WARNING:django.request:Not Found: /people/fetch-one/28
WARNING:django.request:Not Found: /favicon.ico
ERROR:human_api:87 | Expecting value: line 1 column 1 (char 0)
